Workbook

Sheet Stammdaten
A1: Filialdaten
A2: Filiale_ID | B2: Filiale_Name | C2: Größen_Faktor
A3: F001 | B3: Filiale Nord | C3: 1
A4: F002 | B4: Filiale Süd | C4: 0.8
A5: F003 | B5: Filiale Ost | C5: 0.9
A6: F004 | B6: Filiale West | C6: 1.1
A7: F005 | B7: Filiale Zentrum | C7: 1.3
A9: Artikel
A10: Artikel_ID | B10: Artikel_Name | C10: Kategorie | D10: VK_Preis | E10: Min_Schwund% | F10: Max_Schwund% | G10: Typ_MHD | H10: Max_Liefertage
A11: A001 | B11: Vollmilch 1L | C11: Milch | D11: 1.19 | E11: 3 | F11: 6 | G11: 7 | H11: 3
A12: A002 | B12: Fettarme Milch 1L | C12: Milch | D12: 1.09 | E12: 3 | F12: 5.5 | G12: 7 | H12: 3
A13: A003 | B13: Bio-Milch 1L | C13: Milch | D13: 1.59 | E13: 2.5 | F13: 5 | G13: 7 | H13: 3
A14: A004 | B14: Butter 250g | C14: Butter | D14: 2.29 | E14: 0.5 | F14: 2 | G14: 30 | H14: 10
A15: A005 | B15: Gouda 200g | C15: Käse | D15: 1.99 | E15: 1 | F15: 3 | G15: 21 | H15: 7
A16: A006 | B16: Emmentaler 200g | C16: Käse | D16: 2.49 | E16: 1 | F16: 3 | G16: 21 | H16: 7
A17: A007 | B17: Naturjoghurt 500g | C17: Joghurt | D17: 0.89 | E17: 2 | F17: 5 | G17: 14 | H17: 5
A18: A008 | B18: Fruchtjoghurt 4er | C18: Joghurt | D18: 1.89 | E18: 2.5 | F18: 5.5 | G18: 14 | H18: 5
A19: A009 | B19: Sahne 200ml | C19: Sahne | D19: 0.79 | E19: 1.5 | F19: 3.5 | G19: 10 | H19: 4
A20: A010 | B20: Schmand 200g | C20: Sahne | D20: 0.89 | E20: 1 | F20: 2.5 | G20: 14 | H20: 5
A21: A011 | B21: Mozzarella 125g | C21: Käse | D21: 1.19 | E21: 2 | F21: 5 | G21: 10 | H21: 4
A22: A012 | B22: Quark 500g | C22: Quark | D22: 1.39 | E22: 1.5 | F22: 4 | G22: 14 | H22: 5
... A25: A015 | B25: Frischkäse 200g | C25: Käse | D25: 1.49 | E25: 1 | F25: 3 | G25: 21 | H25: 7
A26: Schwund % Range = Basic Spoilage Risk + Theft Risk + Handling Risk
A28: Saisonal Faktor
A29: Monat_Nr | B29: Monat_Name | C29: Saison_Faktor | D29: Oster_Effekt | E29: Weihnachts_effect | F29: Feiertag_info | G29: Reason
A30: 1 | B30: Januar | C30: 0.9 | D30: Nein | E30: Nein | F30: Neujahr | G30: Post-holiday quiet period
A31: 2 | B31: Februar | C31: 0.85 | D31: Nein | E31: Nein | F31: Karneval | G31: Lowest month + some Karneval
A32: 3 | B32: März | C32: 1.05 | D32: Teilweise | E32: Nein | F32: Oster - Vorbereitung | G32: Often includes Easter prep
A33: 4 | B33: April | C33: 1.25 | D33: Ja | E33: Nein | F33: Ostern - Peak | G33: Easter month (most years) — Aktionen, Peaks
A34: 5 | B34: Mai | C34: 1 | D34: Nein | E34: Nein | F34: Himmelfarht, Pfingsten | G34: Normal + Feiertage (Himmelfahrt, Pfingsten)
A35: 6 | B35: Juni | C35: 1.1 | D35: Nein | E35: Nein | F35: Grillsaison Start | G35: Summer starting, Grillsaison
A36: 7 | B36: Juli | C36: 1.2 | D36: Nein | E36: Nein | F36: Sommerferein, Hitze | G36: Summer heat, spoilage increases
A37: 8 | B37: August | C37: 1.15 | D37: Nein | E37: Nein | F37: Sommerferein | G37: Summer continues, Ferienzeit
A38: 9 | B38: September | C38: 0.95 | D38: Nein | E38: Nein | F38: Back to School | G38: Back to normal
A39: 10 | B39: Oktober | C39: 1 | D39: Nein | E39: Nein | F39: Tag der Einheit | G39: Normal
A40: 11 | B40: November | C40: 1.1 | D40: Nein | E40: Nein | F40: Black Friday | G40: Pre-Christmas buildup, Black Friday
A41: 12 | B41: Dezember | C41: 1.4 | D41: Nein | E41: Ja | F41: Weihnachten + Silvester - Höchster Peak | G41: Highest — Weihnachten + Silvester
A43: Base Stock Table
A44: Artikel_ID | B44: Basis_Soll
A45: A001 | B45: 500
...

Sheet Rohdaten
A1: Inventuroptimierung - Rohdaten
A2: Simulierte Inventurdaten: 5 Filialen · 15 Artikel · 12 Monate · 900 Datensätze
A3: Quelle: Basierend auf Praxiserfahrung im filialbasierten Einzelhandel (Lidl, TEDi)
A4: Filiale_ID | B4: Filiale_Name | C4: Artikel_ID | D4: Artikel_Name | E4: Kategorie | F4: VK_Preis_EUR | G4: Monat_Nr | H4: Monat_Name | I4: Soll_Bestand | J4: Ist_Bestand | K4: Differenz | L4: Bestandsabweichung_% | M4: Abweichung_Typ | N4: Abweichung_Wert_EUR | O4: MHD_Tage | P4: Tage_seit_Lieferung | Q4: Freitag_Schwund_EUR | R4: Samstag_Schwund_EUR | S4: Ereignis | T4: Kassenfehler_Einfluss | U4: Reduziert_Ja_Nein | V4: Rabatt_% | W4: Reduzierter_Preis_EUR | X4: Reduzierte_Menge | Y4: Umsatzverlust_EUR | Z4: MHD_Prozess_Fehler | AA4: Ursachen
A5: F001 | B5: =VLOOKUP(A5,Stammdaten!$A$3:$B$7,2,FALSE) -> Filiale Nord | C5: {=INDEX(Stammdaten!$A$11:$A$25,INT((ROW()-5)/12)+1 - INT((ROW()-5)/180)*15)} -> A001 | D5: =VLOOKUP(C5,Stammdaten!$A$11:$B$25,2,FALSE) -> Vollmilch 1L | E5: =VLOOKUP(C5,Stammdaten!$A$11:$C$25,3,FALSE) -> Milch | F5: =VLOOKUP(C5,Stammdaten!$A$11:$D$25,4,FALSE) -> 1.19 | G5: =MOD(ROW()-5,12)+1 -> 1 | H5: =VLOOKUP(G5,Stammdaten!$A$30:$B$41,2,FALSE) -> Januar | I5: 455 | J5: 437 | K5: =J5-I5 -> -18 | L5: =IF(I5=0,0,(K5)/I5*100) -> -3.956044 | M5: =IF(K5=0,"Perfekt",IF(K5<0,"Schwund","Überbestand")) -> Schwund | N5: =ABS(K5)*F5 -> 21.42 | O5: 6 | P5: 2 | Q5: =IF(K5<0,ABS(N5)*0.25,0) -> 5.355 | R5: =IF(K5<0,ABS(N5)*0.3,0) -> 6.426 | S5: =IF(G5=4,"Ostern",IF(G5=12,"Weihnachten/Silvester",IF(G5=11,"Black Friday",IF(G5=2,"Karneval","Normal")))) -> Normal | T5: 0 | U5: =IF(O5<=0,"Abschreibung",IF(O5<=3,"Ja - 20% Reduzierung","Nein")) -> Nein | V5: =IF(O5<=0,100,IF(O5<=3,20,0)) -> 0 | W5: =IF(V5=100,0,ROUND(F5*(1-V5/100),2)) -> 1.19 | X5: 0 | Y5: =ROUND(X5*F5*(V5/100),2) -> 0 | Z5: Kein MHD - Prozess | AA5: =IF(O5<=0,"Verderb - Abgelaufen",IF(AND(O5<=3,Z5<>"Korrekt",Z5<>"Kein MHD - Prozess"),"MHD - Prozessfehler",IF(K5>0,"Kassenfehler (Überbestand)",IF(AND(ABS(L5)>3,A5="F005"),"Diebstahlrisiko",IF(AND(ABS(L5)>2,P5<2),"Buchungsfehler Wareneingang",IF(ABS(L5)>2,"Prozessfehler","Normal/Gering")))))) -> Prozessfehler
A6: F001 | B6: =VLOOKUP(A6,Stammdaten!$A$3:$B$7,2,FALSE) -> Filiale Nord | C6: {=INDEX(Stammdaten!$A$11:$A$25,INT((ROW()-5)/12)+1 - INT((ROW()-5)/180)*15)} -> A001 | D6: =VLOOKUP(C6,Stammdaten!$A$11:$B$25,2,FALSE) -> Vollmilch 1L | E6: =VLOOKUP(C6,Stammdaten!$A$11:$C$25,3,FALSE) -> Milch | F6: =VLOOKUP(C6,Stammdaten!$A$11:$D$25,4,FALSE) -> 1.19 | G6: =MOD(ROW()-5,12)+1 -> 2 | H6: =VLOOKUP(G6,Stammdaten!$A$30:$B$41,2,FALSE) -> Februar | I6: 438 | J6: 418 | K6: =J6-I6 -> -20 | L6: =IF(I6=0,0,(K6)/I6*100) -> -4.56621 | M6: =IF(K6=0,"Perfekt",IF(K6<0,"Schwund","Überbestand")) -> Schwund | N6: =ABS(K6)*F6 -> 23.8 | O6: 6 | P6: 1 | Q6: =IF(K6<0,ABS(N6)*0.25,0) -> 5.95 | R6: =IF(K6<0,ABS(N6)*0.3,0) -> 7.14 | S6: =IF(G6=4,"Ostern",IF(G6=12,"Weihnachten/Silvester",IF(G6=11,"Black Friday",IF(G6=2,"Karneval","Normal")))) -> Karneval | T6: 0 | U6: =IF(O6<=0,"Abschreibung",IF(O6<=3,"Ja - 20% Reduzierung","Nein")) -> Nein | V6: =IF(O6<=0,100,IF(O6<=3,20,0)) -> 0 | W6: =IF(V6=100,0,ROUND(F6*(1-V6/100),2)) -> 1.19 | X6: 0 | Y6: =ROUND(X6*F6*(V6/100),2) -> 0 | Z6: Kein MHD - Prozess | AA6: =IF(O6<=0,"Verderb - Abgelaufen",IF(AND(O6<=3,Z6<>"Korrekt",Z6<>"Kein MHD - Prozess"),"MHD - Prozessfehler",IF(K6>0,"Kassenfehler (Überbestand)",IF(AND(ABS(L6)>3,A6="F005"),"Diebstahlrisiko",IF(AND(ABS(L6)>2,P6<2),"Buchungsfehler Wareneingang",IF(ABS(L6)>2,"Prozessfehler","Normal/Gering")))))) -> Buchungsfehler Wareneingang
A7: F001 | B7: =VLOOKUP(A7,Stammdaten!$A$3:$B$7,2,FALSE) -> Filiale Nord | C7: {=INDEX(Stammdaten!$A$11:$A$25,INT((ROW()-5)/12)+1 - INT((ROW()-5)/180)*15)} -> A001 | D7: =VLOOKUP(C7,Stammdaten!$A$11:$B$25,2,FALSE) -> Vollmilch 1L | E7: =VLOOKUP(C7,Stammdaten!$A$11:$C$25,3,FALSE) -> Milch | F7: =VLOOKUP(C7,Stammdaten!$A$11:$D$25,4,FALSE) -> 1.19 | G7: =MOD(ROW()-5,12)+1 -> 3 | H7: =VLOOKUP(G7,Stammdaten!$A$30:$B$41,2,FALSE) -> März | I7: 520 | J7: 524 | K7: =J7-I7 -> 4 | L7: =IF(I7=0,0,(K7)/I7*100) -> 0.76923077 | M7: =IF(K7=0,"Perfekt",IF(K7<0,"Schwund","Überbestand")) -> Überbestand | N7: =ABS(K7)*F7 -> 4.76 | O7: 1 | P7: 2 | Q7: =IF(K7<0,ABS(N7)*0.25,0) -> 0 | R7: =IF(K7<0,ABS(N7)*0.3,0) -> 0 | S7: =IF(G7=4,"Ostern",IF(G7=12,"Weihnachten/Silvester",IF(G7=11,"Black Friday",IF(G7=2,"Karneval","Normal")))) -> Normal | T7: 4 | U7: =IF(O7<=0,"Abschreibung",IF(O7<=3,"Ja - 20% Reduzierung","Nein")) -> Ja - 20% Reduzierung | V7: =IF(O7<=0,100,IF(O7<=3,20,0)) -> 20 | W7: =IF(V7=100,0,ROUND(F7*(1-V7/100),2)) -> 0.95 | X7: 26 | Y7: =ROUND(X7*F7*(V7/100),2) -> 6.19 | Z7: Korrekt | AA7: =IF(O7<=0,"Verderb - Abgelaufen",IF(AND(O7<=3,Z7<>"Korrekt",Z7<>"Kein MHD - Prozess"),"MHD - Prozessfehler",IF(K7>0,"Kassenfehler (Überbestand)",IF(AND(ABS(L7)>3,A7="F005"),"Diebstahlrisiko",IF(AND(ABS(L7)>2,P7<2),"Buchungsfehler Wareneingang",IF(ABS(L7)>2,"Prozessfehler","Normal/Gering")))))) -> Kassenfehler (Überbestand)
A8: F001 | B8: =VLOOKUP(A8,Stammdaten!$A$3:$B$7,2,FALSE) -> Filiale Nord | C8: {=INDEX(Stammdaten!$A$11:$A$25,INT((ROW()-5)/12)+1 - INT((ROW()-5)/180)*15)} -> A001 | D8: =VLOOKUP(C8,Stammdaten!$A$11:$B$25,2,FALSE) -> Vollmilch 1L | E8: =VLOOKUP(C8,Stammdaten!$A$11:$C$25,3,FALSE) -> Milch | F8: =VLOOKUP(C8,Stammdaten!$A$11:$D$25,4,FALSE) -> 1.19 | G8: =MOD(ROW()-5,12)+1 -> 4 | H8: =VLOOKUP(G8,Stammdaten!$A$30:$B$41,2,FALSE) -> April | I8: 656 | J8: 627 | K8: =J8-I8 -> -29 | L8: =IF(I8=0,0,(K8)/I8*100) -> -4.4207317 | M8: =IF(K8=0,"Perfekt",IF(K8<0,"Schwund","Überbestand")) -> Schwund | N8: =ABS(K8)*F8 -> 34.51 | O8: 4 | P8: 0 | Q8: =IF(K8<0,ABS(N8)*0.25,0) -> 8.6275 | R8: =IF(K8<0,ABS(N8)*0.3,0) -> 10.353 | S8: =IF(G8=4,"Ostern",IF(G8=12,"Weihnachten/Silvester",IF(G8=11,"Black Friday",IF(G8=2,"Karneval","Normal")))) -> Ostern | T8: 0 | U8: =IF(O8<=0,"Abschreibung",IF(O8<=3,"Ja - 20% Reduzierung","Nein")) -> Nein | V8: =IF(O8<=0,100,IF(O8<=3,20,0)) -> 0 | W8: =IF(V8=100,0,ROUND(F8*(1-V8/100),2)) -> 1.19 | X8: 0 | Y8: =ROUND(X8*F8*(V8/100),2) -> 0 | Z8: Kein MHD - Prozess | AA8: =IF(O8<=0,"Verderb - Abgelaufen",IF(AND(O8<=3,Z8<>"Korrekt",Z8<>"Kein MHD - Prozess"),"MHD - Prozessfehler",IF(K8>0,"Kassenfehler (Überbestand)",IF(AND(ABS(L8)>3,A8="F005"),"Diebstahlrisiko",IF(AND(ABS(L8)>2,P8<2),"Buchungsfehler Wareneingang",IF(ABS(L8)>2,"Prozessfehler","Normal/Gering")))))) -> Buchungsfehler Wareneingang
A9: F001 | B9: =VLOOKUP(A9,Stammdaten!$A$3:$B$7,2,FALSE) -> Filiale Nord | C9: {=INDEX(Stammdaten!$A$11:$A$25,INT((ROW()-5)/12)+1 - INT((ROW()-5)/180)*15)} -> A001 | D9: =VLOOKUP(C9,Stammdaten!$A$11:$B$25,2,FALSE) -> Vollmilch 1L | E9: =VLOOKUP(C9,Stammdaten!$A$11:$C$25,3,FALSE) -> Milch | F9: =VLOOKUP(C9,Stammdaten!$A$11:$D$25,4,FALSE) -> 1.19 | G9: =MOD(ROW()-5,12)+1 -> 5 | H9: =VLOOKUP(G9,Stammdaten!$A$30:$B$41,2,FALSE) -> Mai | I9: 485 | J9: 463 | K9: =J9-I9 -> -22 | L9: =IF(I9=0,0,(K9)/I9*100) -> -4.5360825 | M9: =IF(K9=0,"Perfekt",IF(K9<0,"Schwund","Überbestand")) -> Schwund | N9: =ABS(K9)*F9 -> 26.18 | O9: 0 | P9: 1 | Q9: =IF(K9<0,ABS(N9)*0.25,0) -> 6.545 | R9: =IF(K9<0,ABS(N9)*0.3,0) -> 7.854 | S9: =IF(G9=4,"Ostern",IF(G9=12,"Weihnachten/Silvester",IF(G9=11,"Black Friday",IF(G9=2,"Karneval","Normal")))) -> Normal | T9: 0 | U9: =IF(O9<=0,"Abschreibung",IF(O9<=3,"Ja - 20% Reduzierung","Nein")) -> Abschreibung | V9: =IF(O9<=0,100,IF(O9<=3,20,0)) -> 100 | W9: =IF(V9=100,0,ROUND(F9*(1-V9/100),2)) -> 0 | X9: 5 | Y9: =ROUND(X9*F9*(V9/100),2) -> 5.95 | Z9: Korrekt | AA9: =IF(O9<=0,"Verderb - Abgelaufen",IF(AND(O9<=3,Z9<>"Korrekt",Z9<>"Kein MHD - Prozess"),"MHD - Prozessfehler",IF(K9>0,"Kassenfehler (Überbestand)",IF(AND(ABS(L9)>3,A9="F005"),"Diebstahlrisiko",IF(AND(ABS(L9)>2,P9<2),"Buchungsfehler Wareneingang",IF(ABS(L9)>2,"Prozessfehler","Normal/Gering")))))) -> Verderb - Abgelaufen
A10: F001 | B10: =VLOOKUP(A10,Stammdaten!$A$3:$B$7,2,FALSE) -> Filiale Nord | C10: {=INDEX(Stammdaten!$A$11:$A$25,INT((ROW()-5)/12)+1 - INT((ROW()-5)/180)*15)} -> A001 | D10: =VLOOKUP(C10,Stammdaten!$A$11:$B$25,2,FALSE) -> Vollmilch 1L | E10: =VLOOKUP(C10,Stammdaten!$A$11:$C$25,3,FALSE) -> Milch | F10: =VLOOKUP(C10,Stammdaten!$A$11:$D$25,4,FALSE) -> 1.19 | G10: =MOD(ROW()-5,12)+1 -> 6 | H10: =VLOOKUP(G10,Stammdaten!$A$30:$B$41,2,FALSE) -> Juni | I10: 523 | J10: 527 | K10: =J10-I10 -> 4 | L10: =IF(I10=0,0,(K10)/I10*100) -> 0.76481836 | M10: =IF(K10=0,"Perfekt",IF(K10<0,"Schwund","Überbestand")) -> Überbestand | N10: =ABS(K10)*F10 -> 4.76 | O10: 6 | P10: 2 | Q10: =IF(K10<0,ABS(N10)*0.25,0) -> 0 | R10: =IF(K10<0,ABS(N10)*0.3,0) -> 0 | S10: =IF(G10=4,"Ostern",IF(G10=12,"Weihnachten/Silvester",IF(G10=11,"Black Friday",IF(G10=2,"Karneval","Normal")))) -> Normal | T10: 4 | U10: =IF(O10<=0,"Abschreibung",IF(O10<=3,"Ja - 20% Reduzierung","Nein")) -> Nein | V10: =IF(O10<=0,100,IF(O10<=3,20,0)) -> 0 | W10: =IF(V10=100,0,ROUND(F10*(1-V10/100),2)) -> 1.19 | X10: 0 | Y10: =ROUND(X10*F10*(V10/100),2) -> 0 | Z10: Kein MHD - Prozess | AA10: =IF(O10<=0,"Verderb - Abgelaufen",IF(AND(O10<=3,Z10<>"Korrekt",Z10<>"Kein MHD - Prozess"),"MHD - Prozessfehler",IF(K10>0,"Kassenfehler (Überbestand)",IF(AND(ABS(L10)>3,A10="F005"),"Diebstahlrisiko",IF(AND(ABS(L10)>2,P10<2),"Buchungsfehler Wareneingang",IF(ABS(L10)>2,"Prozessfehler","Normal/Gering")))))) -> Kassenfehler (Überbestand)
A11: F001 | B11: =VLOOKUP(A11,Stammdaten!$A$3:$B$7,2,FALSE) -> Filiale Nord | C11: {=INDEX(Stammdaten!$A$11:$A$25,INT((ROW()-5)/12)+1 - INT((ROW()-5)/180)*15)} -> A001 | D11: =VLOOKUP(C11,Stammdaten!$A$11:$B$25,2,FALSE) -> Vollmilch 1L | E11: =VLOOKUP(C11,Stammdaten!$A$11:$C$25,3,FALSE) -> Milch | F11: =VLOOKUP(C11,Stammdaten!$A$11:$D$25,4,FALSE) -> 1.19 | G11: =MOD(ROW()-5,12)+1 -> 7 | H11: =VLOOKUP(G11,Stammdaten!$A$30:$B$41,2,FALSE) -> Juli | I11: 600 | J11: 565 | K11: =J11-I11 -> -35 | L11: =IF(I11=0,0,(K11)/I11*100) -> -5.8333333 | M11: =IF(K11=0,"Perfekt",IF(K11<0,"Schwund","Überbestand")) -> Schwund | N11: =ABS(K11)*F11 -> 41.65 | O11: 7 | P11: 1 | Q11: =IF(K11<0,ABS(N11)*0.25,0) -> 10.4125 | R11: =IF(K11<0,ABS(N11)*0.3,0) -> 12.495 | S11: =IF(G11=4,"Ostern",IF(G11=12,"Weihnachten/Silvester",IF(G11=11,"Black Friday",IF(G11=2,"Karneval","Normal")))) -> Normal | T11: 0 | U11: =IF(O11<=0,"Abschreibung",IF(O11<=3,"Ja - 20% Reduzierung","Nein")) -> Nein | V11: =IF(O11<=0,100,IF(O11<=3,20,0)) -> 0 | W11: =IF(V11=100,0,ROUND(F11*(1-V11/100),2)) -> 1.19 | X11: 0 | Y11: =ROUND(X11*F11*(V11/100),2) -> 0 | Z11: Kein MHD - Prozess | AA11: =IF(O11<=0,"Verderb - Abgelaufen",IF(AND(O11<=3,Z11<>"Korrekt",Z11<>"Kein MHD - Prozess"),"MHD - Prozessfehler",IF(K11>0,"Kassenfehler (Überbestand)",IF(AND(ABS(L11)>3,A11="F005"),"Diebstahlrisiko",IF(AND(ABS(L11)>2,P11<2),"Buchungsfehler Wareneingang",IF(ABS(L11)>2,"Prozessfehler","Normal/Gering")))))) -> Buchungsfehler Wareneingang
A12: F001 | B12: =VLOOKUP(A12,Stammdaten!$A$3:$B$7,2,FALSE) -> Filiale Nord | C12: {=INDEX(Stammdaten!$A$11:$A$25,INT((ROW()-5)/12)+1 - INT((ROW()-5)/180)*15)} -> A001 | D12: =VLOOKUP(C12,Stammdaten!$A$11:$B$25,2,FALSE) -> Vollmilch 1L | E12: =VLOOKUP(C12,Stammdaten!$A$11:$C$25,3,FALSE) -> Milch | F12: =VLOOKUP(C12,Stammdaten!$A$11:$D$25,4,FALSE) -> 1.19 | G12: =MOD(ROW()-5,12)+1 -> 8 | H12: =VLOOKUP(G12,Stammdaten!$A$30:$B$41,2,FALSE) -> August | I12: 604 | J12: 612 | K12: =J12-I12 -> 8 | L12: =IF(I12=0,0,(K12)/I12*100) -> 1.3245033 | M12: =IF(K12=0,"Perfekt",IF(K12<0,"Schwund","Überbestand")) -> Überbestand | N12: =ABS(K12)*F12 -> 9.52 | O12: 3 | P12: 0 | Q12: =IF(K12<0,ABS(N12)*0.25,0) -> 0 | R12: =IF(K12<0,ABS(N12)*0.3,0) -> 0 | S12: =IF(G12=4,"Ostern",IF(G12=12,"Weihnachten/Silvester",IF(G12=11,"Black Friday",IF(G12=2,"Karneval","Normal")))) -> Normal | T12: 8 | U12: =IF(O12<=0,"Abschreibung",IF(O12<=3,"Ja - 20% Reduzierung","Nein")) -> Ja - 20% Reduzierung | V12: =IF(O12<=0,100,IF(O12<=3,20,0)) -> 20 | W12: =IF(V12=100,0,ROUND(F12*(1-V12/100),2)) -> 0.95 | X12: 48 | Y12: =ROUND(X12*F12*(V12/100),2) -> 11.42 | Z12: Korrekt | AA12: =IF(O12<=0,"Verderb - Abgelaufen",IF(AND(O12<=3,Z12<>"Korrekt",Z12<>"Kein MHD - Prozess"),"MHD - Prozessfehler",IF(K12>0,"Kassenfehler (Überbestand)",IF(AND(ABS(L12)>3,A12="F005"),"Diebstahlrisiko",IF(AND(ABS(L12)>2,P12<2),"Buchungsfehler Wareneingang",IF(ABS(L12)>2,"Prozessfehler","Normal/Gering")))))) -> Kassenfehler (Überbestand)
A13: F001 | B13: =VLOOKUP(A13,Stammdaten!$A$3:$B$7,2,FALSE) -> Filiale Nord | C13: {=INDEX(Stammdaten!$A$11:$A$25,INT((ROW()-5)/12)+1 - INT((ROW()-5)/180)*15)} -> A001 | D13: =VLOOKUP(C13,Stammdaten!$A$11:$B$25,2,FALSE) -> Vollmilch 1L | E13: =VLOOKUP(C13,Stammdaten!$A$11:$C$25,3,FALSE) -> Milch | F13: =VLOOKUP(C13,Stammdaten!$A$11:$D$25,4,FALSE) -> 1.19 | G13: =MOD(ROW()-5,12)+1 -> 9 | H13: =VLOOKUP(G13,Stammdaten!$A$30:$B$41,2,FALSE) -> September | I13: 470 | J13: 443 | K13: =J13-I13 -> -27 | L13: =IF(I13=0,0,(K13)/I13*100) -> -5.7446809 | M13: =IF(K13=0,"Perfekt",IF(K13<0,"Schwund","Überbestand")) -> Schwund | N13: =ABS(K13)*F13 -> 32.13 | O13: 5 | P13: 3 | Q13: =IF(K13<0,ABS(N13)*0.25,0) -> 8.0325 | R13: =IF(K13<0,ABS(N13)*0.3,0) -> 9.639 | S13: =IF(G13=4,"Ostern",IF(G13=12,"Weihnachten/Silvester",IF(G13=11,"Black Friday",IF(G13=2,"Karneval","Normal")))) -> Normal | T13: 0 | U13: =IF(O13<=0,"Abschreibung",IF(O13<=3,"Ja - 20% Reduzierung","Nein")) -> Nein | V13: =IF(O13<=0,100,IF(O13<=3,20,0)) -> 0 | W13: =IF(V13=100,0,ROUND(F13*(1-V13/100),2)) -> 1.19 | X13: 0 | Y13: =ROUND(X13*F13*(V13/100),2) -> 0 | Z13: Kein MHD - Prozess | AA13: =IF(O13<=0,"Verderb - Abgelaufen",IF(AND(O13<=3,Z13<>"Korrekt",Z13<>"Kein MHD - Prozess"),"MHD - Prozessfehler",IF(K13>0,"Kassenfehler (Überbestand)",IF(AND(ABS(L13)>3,A13="F005"),"Diebstahlrisiko",IF(AND(ABS(L13)>2,P13<2),"Buchungsfehler Wareneingang",IF(ABS(L13)>2,"Prozessfehler","Normal/Gering")))))) -> Prozessfehler
A14: F001 | B14: =VLOOKUP(A14,Stammdaten!$A$3:$B$7,2,FALSE) -> Filiale Nord | C14: {=INDEX(Stammdaten!$A$11:$A$25,INT((ROW()-5)/12)+1 - INT((ROW()-5)/180)*15)} -> A001 | D14: =VLOOKUP(C14,Stammdaten!$A$11:$B$25,2,FALSE) -> Vollmilch 1L | E14: =VLOOKUP(C14,Stammdaten!$A$11:$C$25,3,FALSE) -> Milch | F14: =VLOOKUP(C14,Stammdaten!$A$11:$D$25,4,FALSE) -> 1.19 | G14: =MOD(ROW()-5,12)+1 -> 10 | H14: =VLOOKUP(G14,Stammdaten!$A$30:$B$41,2,FALSE) -> Oktober | I14: 505 | J14: 511 | K14: =J14-I14 -> 6 | L14: =IF(I14=0,0,(K14)/I14*100) -> 1.1881188 | M14: =IF(K14=0,"Perfekt",IF(K14<0,"Schwund","Überbestand")) -> Überbestand | N14: =ABS(K14)*F14 -> 7.14 | O14: 0 | P14: 1 | Q14: =IF(K14<0,ABS(N14)*0.25,0) -> 0 | R14: =IF(K14<0,ABS(N14)*0.3,0) -> 0 | S14: =IF(G14=4,"Ostern",IF(G14=12,"Weihnachten/Silvester",IF(G14=11,"Black Friday",IF(G14=2,"Karneval","Normal")))) -> Normal | T14: 6 | U14: =IF(O14<=0,"Abschreibung",IF(O14<=3,"Ja - 20% Reduzierung","Nein")) -> Abschreibung | V14: =IF(O14<=0,100,IF(O14<=3,20,0)) -> 100 | W14: =IF(V14=100,0,ROUND(F14*(1-V14/100),2)) -> 0 | X14: 5 | Y14: =ROUND(X14*F14*(V14/100),2) -> 5.95 | Z14: Korrekt | AA14: =IF(O14<=0,"Verderb - Abgelaufen",IF(AND(O14<=3,Z14<>"Korrekt",Z14<>"Kein MHD - Prozess"),"MHD - Prozessfehler",IF(K14>0,"Kassenfehler (Überbestand)",IF(AND(ABS(L14)>3,A14="F005"),"Diebstahlrisiko",IF(AND(ABS(L14)>2,P14<2),"Buchungsfehler Wareneingang",IF(ABS(L14)>2,"Prozessfehler","Normal/Gering")))))) -> Verderb - Abgelaufen
A15: F001 | B15: =VLOOKUP(A15,Stammdaten!$A$3:$B$7,2,FALSE) -> Filiale Nord | C15: {=INDEX(Stammdaten!$A$11:$A$25,INT((ROW()-5)/12)+1 - INT((ROW()-5)/180)*15)} -> A001 | D15: =VLOOKUP(C15,Stammdaten!$A$11:$B$25,2,FALSE) -> Vollmilch 1L | E15: =VLOOKUP(C15,Stammdaten!$A$11:$C$25,3,FALSE) -> Milch | F15: =VLOOKUP(C15,Stammdaten!$A$11:$D$25,4,FALSE) -> 1.19 | G15: =MOD(ROW()-5,12)+1 -> 11 | H15: =VLOOKUP(G15,Stammdaten!$A$30:$B$41,2,FALSE) -> November | I15: 578 | J15: 555 | K15: =J15-I15 -> -23 | L15: =IF(I15=0,0,(K15)/I15*100) -> -3.9792388 | M15: =IF(K15=0,"Perfekt",IF(K15<0,"Schwund","Überbestand")) -> Schwund | N15: =ABS(K15)*F15 -> 27.37 | O15: 6 | P15: 0 | Q15: =IF(K15<0,ABS(N15)*0.25,0) -> 6.8425 | R15: =IF(K15<0,ABS(N15)*0.3,0) -> 8.211 | S15: =IF(G15=4,"Ostern",IF(G15=12,"Weihnachten/Silvester",IF(G15=11,"Black Friday",IF(G15=2,"Karneval","Normal")))) -> Black Friday | T15: 0 | U15: =IF(O15<=0,"Abschreibung",IF(O15<=3,"Ja - 20% Reduzierung","Nein")) -> Nein | V15: =IF(O15<=0,100,IF(O15<=3,20,0)) -> 0 | W15: =IF(V15=100,0,ROUND(F15*(1-V15/100),2)) -> 1.19 | X15: 0 | Y15: =ROUND(X15*F15*(V15/100),2) -> 0 | Z15: Kein MHD - Prozess | AA15: =IF(O15<=0,"Verderb - Abgelaufen",IF(AND(O15<=3,Z15<>"Korrekt",Z15<>"Kein MHD - Prozess"),"MHD - Prozessfehler",IF(K15>0,"Kassenfehler (Überbestand)",IF(AND(ABS(L15)>3,A15="F005"),"Diebstahlrisiko",IF(AND(ABS(L15)>2,P15<2),"Buchungsfehler Wareneingang",IF(ABS(L15)>2,"Prozessfehler","Normal/Gering")))))) -> Buchungsfehler Wareneingang
A16: F001 | B16: =VLOOKUP(A16,Stammdaten!$A$3:$B$7,2,FALSE) -> Filiale Nord | C16: {=INDEX(Stammdaten!$A$11:$A$25,INT((ROW()-5)/12)+1 - INT((ROW()-5)/180)*15)} -> A001 | D16: =VLOOKUP(C16,Stammdaten!$A$11:$B$25,2,FALSE) -> Vollmilch 1L | E16: =VLOOKUP(C16,Stammdaten!$A$11:$C$25,3,FALSE) -> Milch | F16: =VLOOKUP(C16,Stammdaten!$A$11:$D$25,4,FALSE) -> 1.19 | G16: =MOD(ROW()-5,12)+1 -> 12 | H16: =VLOOKUP(G16,Stammdaten!$A$30:$B$41,2,FALSE) -> Dezember | I16: 707 | J16: 668 | K16: =J16-I16 -> -39 | L16: =IF(I16=0,0,(K16)/I16*100) -> -5.5162659 | M16: =IF(K16=0,"Perfekt",IF(K16<0,"Schwund","Überbestand")) -> Schwund | N16: =ABS(K16)*F16 -> 46.41 | O16: 4 | P16: 1 | Q16: =IF(K16<0,ABS(N16)*0.25,0) -> 11.6025 | R16: =IF(K16<0,ABS(N16)*0.3,0) -> 13.923 | S16: =IF(G16=4,"Ostern",IF(G16=12,"Weihnachten/Silvester",IF(G16=11,"Black Friday",IF(G16=2,"Karneval","Normal")))) -> Weihnachten/Silvester | T16: 0 | U16: =IF(O16<=0,"Abschreibung",IF(O16<=3,"Ja - 20% Reduzierung","Nein")) -> Nein | V16: =IF(O16<=0,100,IF(O16<=3,20,0)) -> 0 | W16: =IF(V16=100,0,ROUND(F16*(1-V16/100),2)) -> 1.19 | X16: 0 | Y16: =ROUND(X16*F16*(V16/100),2) -> 0 | Z16: Kein MHD - Prozess | AA16: =IF(O16<=0,"Verderb - Abgelaufen",IF(AND(O16<=3,Z16<>"Korrekt",Z16<>"Kein MHD - Prozess"),"MHD - Prozessfehler",IF(K16>0,"Kassenfehler (Überbestand)",IF(AND(ABS(L16)>3,A16="F005"),"Diebstahlrisiko",IF(AND(ABS(L16)>2,P16<2),"Buchungsfehler Wareneingang",IF(ABS(L16)>2,"Prozessfehler","Normal/Gering")))))) -> Buchungsfehler Wareneingang
... A904: F005 | B904: =VLOOKUP(A904,Stammdaten!$A$3:$B$7,2,FALSE) -> Filiale Zentrum | C904: {=INDEX(Stammdaten!$A$11:$A$25,INT((ROW()-5)/12)+1 - INT((ROW()-5)/180)*15)} -> A015 | D904: =VLOOKUP(C904,Stammdaten!$A$11:$B$25,2,FALSE) -> Frischkäse 200g | E904: =VLOOKUP(C904,Stammdaten!$A$11:$C$25,3,FALSE) -> Käse | F904: =VLOOKUP(C904,Stammdaten!$A$11:$D$25,4,FALSE) -> 1.49 | G904: =MOD(ROW()-5,12)+1 -> 12 | H904: =VLOOKUP(G904,Stammdaten!$A$30:$B$41,2,FALSE) -> Dezember | I904: 371 | J904: 373 | K904: =J904-I904 -> 2 | L904: =IF(I904=0,0,(K904)/I904*100) -> 0.53908356 | M904: =IF(K904=0,"Perfekt",IF(K904<0,"Schwund","Überbestand")) -> Überbestand | N904: =ABS(K904)*F904 -> 2.98 | O904: 9 | P904: 0 | Q904: =IF(K904<0,ABS(N904)*0.25,0) -> 0 | R904: =IF(K904<0,ABS(N904)*0.3,0) -> 0 | S904: =IF(G904=4,"Ostern",IF(G904=12,"Weihnachten/Silvester",IF(G904=11,"Black Friday",IF(G904=2,"Karneval","Normal")))) -> Weihnachten/Silvester | T904: 2 | U904: =IF(O904<=0,"Abschreibung",IF(O904<=3,"Ja - 20% Reduzierung","Nein")) -> Nein | V904: =IF(O904<=0,100,IF(O904<=3,20,0)) -> 0 | W904: =IF(V904=100,0,ROUND(F904*(1-V904/100),2)) -> 1.49 | X904: 0 | Y904: =ROUND(X904*F904*(V904/100),2) -> 0 | Z904: Kein MHD - Prozess | AA904: =IF(O904<=0,"Verderb - Abgelaufen",IF(AND(O904<=3,Z904<>"Korrekt",Z904<>"Kein MHD - Prozess"),"MHD - Prozessfehler",IF(K904>0,"Kassenfehler (Überbestand)",IF(AND(ABS(L904)>3,A904="F005"),"Diebstahlrisiko",IF(AND(ABS(L904)>2,P904<2),"Buchungsfehler Wareneingang",IF(ABS(L904)>2,"Prozessfehler","Normal/Gering")))))) -> Kassenfehler (Überbestand)
H905: Min | I905: =MIN(I5:I904) -> 99 | K905: =MIN(K5:K904) -> -63 | T905: =COUNTIF(T5:T904,"<>0") -> 150
H906: Max | I906: =MAX(I5:I904) -> 1011 | K906: =MAX(K5:K904) -> 8 | M906: =COUNTIF(M5:M904,"Schwund") -> 669
H907: Avg | I907: =AVERAGE(I5:I904) -> 343.27444 | M907: =COUNTIF(M5:M904,"Überbestand") -> 150
M908: =COUNTIF(M5:M904,"Perfekt") -> 81
A927: Formula for Soll_Bestand: | B927: ROUND(VLOOKUP(C904;Stammdaten!$A$45:$B$59;2;FALSE)*VLOOKUP(A904;Stammdaten!$A$3:$C$7;3;FALSE)*VLOOKUP(G904;Stammdaten!$A$30:$C$41;3;FALSE)*(1+(RANDBETWEEN(-5;5)/100));0)
A928: Formula for Kassenfehler_einfluss: | B928: IF(RANDBETWEEN(1;100)<=15;RANDBETWEEN(1;8);0)
A929: Formula for Ist_Bestand: | B929: IF(T904>0;I904+T904;IF(RANDBETWEEN(1;100)<=12;I904;I904-ROUND(I904*(RANDBETWEEN(VLOOKUP(C904;Stammdaten!$A$11:$F$25;5;FALSE)*100;VLOOKUP(C904;Stammdaten!$A$11:$F$25;6;FALSE)*100)/10000)*VLOOKUP(G904;Stammdaten!$A$30:$C$41;3;FALSE);0)))
A930: Formula for MHD_Tage: | B930: VLOOKUP(C904;Stammdaten!$A$11:$G$25;7;FALSE)-P904+RANDBETWEEN(-1;1)
A931: Formula for Tage_Seit_lieferung: | B931: RANDBETWEEN(0;VLOOKUP(C904;Stammdaten!$A$11:$H$25;8;FALSE))
A932: Formula for Reduzeirte Menge: | B932: IF(V904=0;0;IF(V904=100;ROUND(I904*RANDBETWEEN(1;3)/100;0);ROUND(I904*RANDBETWEEN(5;15)/100;0)))
A933: Formula for MHD Prozess Failure: | B933: IF(O904>3;"Kein MHD - Prozess";IF(RANDBETWEEN(1;100)<=12;IF(RANDBETWEEN(1;4)=1;"Zählfehler";IF(RANDBETWEEN(1;4)=2;"Produkt Übersehen";IF(RANDBETWEEN(1;4)=3;"Eingabefehler";"FIFO - Fehler")));"Korrekt"))

Sheet ABC_Analyse
A1: ABC - Analyse - Inventuroptimierung
A2: Simulierte Inventurdaten: 5 Filialen · 15 Artikel · 12 Monate · 900 Datensätze
A4: Artikel_ID | B4: Artikel_Name | C4: Kategorie | D4: VK_Preis_EUR | E4: Gesamt_Soll | F4: Gesamt_Ist | G4: Gesamt_Differenz | H4: Gesamt_Schwund_Wert_EUR | I4: Ø_Schwundquote_% | J4: Anteil_am_Gesamtschwund_% | K4: Kumuliert_% | L4: ABC_Klasse | M4: Zähl_Frequenz
A5: A008 | B5: =VLOOKUP(A5,Stammdaten!$A$11:$B$25,2,FALSE) -> Fruchtjoghurt 4er | C5: =VLOOKUP(A5,Stammdaten!$A$11:$C$25,3,FALSE) -> Joghurt | D5: =VLOOKUP(A5,Stammdaten!$A$11:$D$25,4,FALSE) -> 1.89 | E5: =SUMIFS(Rohdaten!I:I,Rohdaten!C:C,A5) -> 23066 | F5: =SUMIFS(Rohdaten!J:J,Rohdaten!C:C,A5) -> 22403 | G5: =F5-E5 -> -663 | H5: =SUMIFS(Rohdaten!N:N,Rohdaten!C:C,A5) -> 1442.07 | I5: =AVERAGEIFS(Rohdaten!L:L,Rohdaten!C:C,A5) -> -2.8688886 | J5: =H5/$H$20*100 -> 12.483617 | K5: =J5 -> 12.483617 | L5: =IF(K5<=80,"A",IF(K5<=95,"B","C")) -> A | M5: =IF(L5="A","Wöchentlich",IF(L5="B","Monatlich","Quartalsweise")) -> Wöchentlich
A6: A001 | B6: =VLOOKUP(A6,Stammdaten!$A$11:$B$25,2,FALSE) -> Vollmilch 1L | C6: =VLOOKUP(A6,Stammdaten!$A$11:$C$25,3,FALSE) -> Milch | D6: =VLOOKUP(A6,Stammdaten!$A$11:$D$25,4,FALSE) -> 1.19 | E6: =SUMIFS(Rohdaten!I:I,Rohdaten!C:C,A6) -> 33237 | F6: =SUMIFS(Rohdaten!J:J,Rohdaten!C:C,A6) -> 32178 | G6: =F6-E6 -> -1059 | H6: =SUMIFS(Rohdaten!N:N,Rohdaten!C:C,A6) -> 1422.05 | I6: =AVERAGEIFS(Rohdaten!L:L,Rohdaten!C:C,A6) -> -3.1702371 | J6: =H6/$H$20*100 -> 12.310309 | K6: =J6+K5 -> 24.793926 | L6: =IF(K6<=80,"A",IF(K6<=95,"B","C")) -> A | M6: =IF(L6="A","Wöchentlich",IF(L6="B","Monatlich","Quartalsweise")) -> Wöchentlich
A7: A002 | B7: =VLOOKUP(A7,Stammdaten!$A$11:$B$25,2,FALSE) -> Fettarme Milch 1L | C7: =VLOOKUP(A7,Stammdaten!$A$11:$C$25,3,FALSE) -> Milch | D7: =VLOOKUP(A7,Stammdaten!$A$11:$D$25,4,FALSE) -> 1.09 | E7: =SUMIFS(Rohdaten!I:I,Rohdaten!C:C,A7) -> 29658 | F7: =SUMIFS(Rohdaten!J:J,Rohdaten!C:C,A7) -> 28602 | G7: =F7-E7 -> -1056 | H7: =SUMIFS(Rohdaten!N:N,Rohdaten!C:C,A7) -> 1240.42 | I7: =AVERAGEIFS(Rohdaten!L:L,Rohdaten!C:C,A7) -> -3.3861403 | J7: =H7/$H$20*100 -> 10.737987 | K7: =J7+K6 -> 35.531913 | L7: =IF(K7<=80,"A",IF(K7<=95,"B","C")) -> A | M7: =IF(L7="A","Wöchentlich",IF(L7="B","Monatlich","Quartalsweise")) -> Wöchentlich
A8: A007 | B8: =VLOOKUP(A8,Stammdaten!$A$11:$B$25,2,FALSE) -> Naturjoghurt 500g | C8: =VLOOKUP(A8,Stammdaten!$A$11:$C$25,3,FALSE) -> Joghurt | D8: =VLOOKUP(A8,Stammdaten!$A$11:$D$25,4,FALSE) -> 0.89 | E8: =SUMIFS(Rohdaten!I:I,Rohdaten!C:C,A8) -> 36346 | F8: =SUMIFS(Rohdaten!J:J,Rohdaten!C:C,A8) -> 35341 | G8: =F8-E8 -> -1005 | H8: =SUMIFS(Rohdaten!N:N,Rohdaten!C:C,A8) -> 983.45 | I8: =AVERAGEIFS(Rohdaten!L:L,Rohdaten!C:C,A8) -> -2.7308621 | J8: =H8/$H$20*100 -> 8.5134656 | K8: =J8+K7 -> 44.045379 | L8: =IF(K8<=80,"A",IF(K8<=95,"B","C")) -> A | M8: =IF(L8="A","Wöchentlich",IF(L8="B","Monatlich","Quartalsweise")) -> Wöchentlich
A9: A012 | B9: =VLOOKUP(A9,Stammdaten!$A$11:$B$25,2,FALSE) -> Quark 500g | C9: =VLOOKUP(A9,Stammdaten!$A$11:$C$25,3,FALSE) -> Quark | D9: =VLOOKUP(A9,Stammdaten!$A$11:$D$25,4,FALSE) -> 1.39 | E9: =SUMIFS(Rohdaten!I:I,Rohdaten!C:C,A9) -> 26445 | F9: =SUMIFS(Rohdaten!J:J,Rohdaten!C:C,A9) -> 25847 | G9: =F9-E9 -> -598 | H9: =SUMIFS(Rohdaten!N:N,Rohdaten!C:C,A9) -> 911.84 | I9: =AVERAGEIFS(Rohdaten!L:L,Rohdaten!C:C,A9) -> -2.1644225 | J9: =H9/$H$20*100 -> 7.8935568 | K9: =J9+K8 -> 51.938935 | L9: =IF(K9<=80,"A",IF(K9<=95,"B","C")) -> A | M9: =IF(L9="A","Wöchentlich",IF(L9="B","Monatlich","Quartalsweise")) -> Wöchentlich
A10: A006 | B10: =VLOOKUP(A10,Stammdaten!$A$11:$B$25,2,FALSE) -> Emmentaler 200g | C10: =VLOOKUP(A10,Stammdaten!$A$11:$C$25,3,FALSE) -> Käse | D10: =VLOOKUP(A10,Stammdaten!$A$11:$D$25,4,FALSE) -> 2.49 | E10: =SUMIFS(Rohdaten!I:I,Rohdaten!C:C,A10) -> 16507 | F10: =SUMIFS(Rohdaten!J:J,Rohdaten!C:C,A10) -> 16233 | G10: =F10-E10 -> -274 | H10: =SUMIFS(Rohdaten!N:N,Rohdaten!C:C,A10) -> 841.62 | I10: =AVERAGEIFS(Rohdaten!L:L,Rohdaten!C:C,A10) -> -1.5758947 | J10: =H10/$H$20*100 -> 7.2856809 | K10: =J10+K9 -> 59.224616 | L10: =IF(K10<=80,"A",IF(K10<=95,"B","C")) -> A | M10: =IF(L10="A","Wöchentlich",IF(L10="B","Monatlich","Quartalsweise")) -> Wöchentlich
A11: A011 | B11: =VLOOKUP(A11,Stammdaten!$A$11:$B$25,2,FALSE) -> Mozzarella 125g | C11: =VLOOKUP(A11,Stammdaten!$A$11:$C$25,3,FALSE) -> Käse | D11: =VLOOKUP(A11,Stammdaten!$A$11:$D$25,4,FALSE) -> 1.19 | E11: =SUMIFS(Rohdaten!I:I,Rohdaten!C:C,A11) -> 19855 | F11: =SUMIFS(Rohdaten!J:J,Rohdaten!C:C,A11) -> 19302 | G11: =F11-E11 -> -553 | H11: =SUMIFS(Rohdaten!N:N,Rohdaten!C:C,A11) -> 743.75 | I11: =AVERAGEIFS(Rohdaten!L:L,Rohdaten!C:C,A11) -> -2.6518332 | J11: =H11/$H$20*100 -> 6.4384463 | K11: =J11+K10 -> 65.663063 | L11: =IF(K11<=80,"A",IF(K11<=95,"B","C")) -> A | M11: =IF(L11="A","Wöchentlich",IF(L11="B","Monatlich","Quartalsweise")) -> Wöchentlich
A12: A013 | B12: =VLOOKUP(A12,Stammdaten!$A$11:$B$25,2,FALSE) -> Skyr 450g | C12: =VLOOKUP(A12,Stammdaten!$A$11:$C$25,3,FALSE) -> Joghurt | D12: =VLOOKUP(A12,Stammdaten!$A$11:$D$25,4,FALSE) -> 1.99 | E12: =SUMIFS(Rohdaten!I:I,Rohdaten!C:C,A12) -> 16417 | F12: =SUMIFS(Rohdaten!J:J,Rohdaten!C:C,A12) -> 16130 | G12: =F12-E12 -> -287 | H12: =SUMIFS(Rohdaten!N:N,Rohdaten!C:C,A12) -> 722.37 | I12: =AVERAGEIFS(Rohdaten!L:L,Rohdaten!C:C,A12) -> -1.6665344 | J12: =H12/$H$20*100 -> 6.2533653 | K12: =J12+K11 -> 71.916428 | L12: =IF(K12<=80,"A",IF(K12<=95,"B","C")) -> A | M12: =IF(L12="A","Wöchentlich",IF(L12="B","Monatlich","Quartalsweise")) -> Wöchentlich
A13: A004 | B13: =VLOOKUP(A13,Stammdaten!$A$11:$B$25,2,FALSE) -> Butter 250g | C13: =VLOOKUP(A13,Stammdaten!$A$11:$C$25,3,FALSE) -> Butter | D13: =VLOOKUP(A13,Stammdaten!$A$11:$D$25,4,FALSE) -> 2.29 | E13: =SUMIFS(Rohdaten!I:I,Rohdaten!C:C,A13) -> 26429 | F13: =SUMIFS(Rohdaten!J:J,Rohdaten!C:C,A13) -> 26196 | G13: =F13-E13 -> -233 | H13: =SUMIFS(Rohdaten!N:N,Rohdaten!C:C,A13) -> 703.03 | I13: =AVERAGEIFS(Rohdaten!L:L,Rohdaten!C:C,A13) -> -0.90832327 | J13: =H13/$H$20*100 -> 6.0859441 | K13: =J13+K12 -> 78.002372 | L13: =IF(K13<=80,"A",IF(K13<=95,"B","C")) -> A | M13: =IF(L13="A","Wöchentlich",IF(L13="B","Monatlich","Quartalsweise")) -> Wöchentlich
A14: A005 | B14: =VLOOKUP(A14,Stammdaten!$A$11:$B$25,2,FALSE) -> Gouda 200g | C14: =VLOOKUP(A14,Stammdaten!$A$11:$C$25,3,FALSE) -> Käse | D14: =VLOOKUP(A14,Stammdaten!$A$11:$D$25,4,FALSE) -> 1.99 | E14: =SUMIFS(Rohdaten!I:I,Rohdaten!C:C,A14) -> 19774 | F14: =SUMIFS(Rohdaten!J:J,Rohdaten!C:C,A14) -> 19519 | G14: =F14-E14 -> -255 | H14: =SUMIFS(Rohdaten!N:N,Rohdaten!C:C,A14) -> 682.57 | I14: =AVERAGEIFS(Rohdaten!L:L,Rohdaten!C:C,A14) -> -1.238595 | J14: =H14/$H$20*100 -> 5.9088273 | K14: =J14+K13 -> 83.911199 | L14: =IF(K14<=80,"A",IF(K14<=95,"B","C")) -> B | M14: =IF(L14="A","Wöchentlich",IF(L14="B","Monatlich","Quartalsweise")) -> Monatlich
A15: A003 | B15: =VLOOKUP(A15,Stammdaten!$A$11:$B$25,2,FALSE) -> Bio-Milch 1L | C15: =VLOOKUP(A15,Stammdaten!$A$11:$C$25,3,FALSE) -> Milch | D15: =VLOOKUP(A15,Stammdaten!$A$11:$D$25,4,FALSE) -> 1.59 | E15: =SUMIFS(Rohdaten!I:I,Rohdaten!C:C,A15) -> 13094 | F15: =SUMIFS(Rohdaten!J:J,Rohdaten!C:C,A15) -> 12871 | G15: =F15-E15 -> -223 | H15: =SUMIFS(Rohdaten!N:N,Rohdaten!C:C,A15) -> 682.11 | I15: =AVERAGEIFS(Rohdaten!L:L,Rohdaten!C:C,A15) -> -1.6231097 | J15: =H15/$H$20*100 -> 5.9048452 | K15: =J15+K14 -> 89.816044 | L15: =IF(K15<=80,"A",IF(K15<=95,"B","C")) -> B | M15: =IF(L15="A","Wöchentlich",IF(L15="B","Monatlich","Quartalsweise")) -> Monatlich
A16: A014 | B16: =VLOOKUP(A16,Stammdaten!$A$11:$B$25,2,FALSE) -> Kefir 500ml | C16: =VLOOKUP(A16,Stammdaten!$A$11:$C$25,3,FALSE) -> Milch | D16: =VLOOKUP(A16,Stammdaten!$A$11:$D$25,4,FALSE) -> 1.39 | E16: =SUMIFS(Rohdaten!I:I,Rohdaten!C:C,A16) -> 9844 | F16: =SUMIFS(Rohdaten!J:J,Rohdaten!C:C,A16) -> 9627 | G16: =F16-E16 -> -217 | H16: =SUMIFS(Rohdaten!N:N,Rohdaten!C:C,A16) -> 398.93 | I16: =AVERAGEIFS(Rohdaten!L:L,Rohdaten!C:C,A16) -> -2.1925603 | J16: =H16/$H$20*100 -> 3.4534311 | K16: =J16+K15 -> 93.269475 | L16: =IF(K16<=80,"A",IF(K16<=95,"B","C")) -> B | M16: =IF(L16="A","Wöchentlich",IF(L16="B","Monatlich","Quartalsweise")) -> Monatlich
A17: A015 | B17: =VLOOKUP(A17,Stammdaten!$A$11:$B$25,2,FALSE) -> Frischkäse 200g | C17: =VLOOKUP(A17,Stammdaten!$A$11:$C$25,3,FALSE) -> Käse | D17: =VLOOKUP(A17,Stammdaten!$A$11:$D$25,4,FALSE) -> 1.49 | E17: =SUMIFS(Rohdaten!I:I,Rohdaten!C:C,A17) -> 13241 | F17: =SUMIFS(Rohdaten!J:J,Rohdaten!C:C,A17) -> 13061 | G17: =F17-E17 -> -180 | H17: =SUMIFS(Rohdaten!N:N,Rohdaten!C:C,A17) -> 366.54 | I17: =AVERAGEIFS(Rohdaten!L:L,Rohdaten!C:C,A17) -> -1.3169085 | J17: =H17/$H$20*100 -> 3.1730395 | K17: =J17+K16 -> 96.442515 | L17: =IF(K17<=80,"A",IF(K17<=95,"B","C")) -> C | M17: =IF(L17="A","Wöchentlich",IF(L17="B","Monatlich","Quartalsweise")) -> Quartalsweise
... A19: A010 | B19: =VLOOKUP(A19,Stammdaten!$A$11:$B$25,2,FALSE) -> Schmand 200g | C19: =VLOOKUP(A19,Stammdaten!$A$11:$C$25,3,FALSE) -> Sahne | D19: =VLOOKUP(A19,Stammdaten!$A$11:$D$25,4,FALSE) -> 0.89 | E19: =SUMIFS(Rohdaten!I:I,Rohdaten!C:C,A19) -> 11844 | F19: =SUMIFS(Rohdaten!J:J,Rohdaten!C:C,A19) -> 11675 | G19: =F19-E19 -> -169 | H19: =SUMIFS(Rohdaten!N:N,Rohdaten!C:C,A19) -> 177.11 | I19: =AVERAGEIFS(Rohdaten!L:L,Rohdaten!C:C,A19) -> -1.3647399 | J19: =H19/$H$20*100 -> 1.5331942 | K19: =J19+K18 -> 100 | L19: =IF(K19<=80,"A",IF(K19<=95,"B","C")) -> C | M19: =IF(L19="A","Wöchentlich",IF(L19="B","Monatlich","Quartalsweise")) -> Quartalsweise
G20: GESAMT | H20: =SUM(H5:H19) -> 11551.7 | J20: =H20/$H$20 -> 1
A22: ABC-ZUSAMMENFASSUNG
A23: ABC_Klasse | B23: Anzahl_Artikel | C23: Anteil_Artikel_% | D23: Anteil_Schwund_% | E23: Zähl_Frequenz
A24: A | B24: =COUNTIF(L5:L19,"A") -> 9 | C24: =B24/15*100 -> 60 | D24: =SUMIFS(H5:H19,L5:L19,"A")/$H$20*100 -> 78.002372 | E24: Wöchentlich
A25: B | B25: =COUNTIF(L5:L19,"B") -> 3 | C25: =B25/15*100 -> 20 | D25: =SUMIFS(H5:H19,L5:L19,"B")/$H$20*100 -> 15.267104 | E25: Monatlich
A26: C | B26: =COUNTIF(L5:L19,"C") -> 3 | C26: =B26/15*100 -> 20 | D26: =SUMIFS(H5:H19,L5:L19,"C")/$H$20*100 -> 6.7305245 | E26: Quartalweise
A66: HANDLUNGSEMPFEHLUNGEN
A67: Empfehlung | B67: Erwarteter Nutzen
A68: A-Artikel wöchentlich per Cycle Count zählen | B68: Frühzeitige Erkennung von Schwund bei den verlustreichsten Produkten
A69: B-Artikel monatlich kontrollieren | B69: Regelmäßige Kontrolle ohne übermäßigen Aufwand
A70: C-Artikel quartalsweise prüfen | B70: Ressourcen-Einsparung bei geringem Risiko
A71: Forecast-Genauigkeit für A-Artikel priorisieren | B71: Bessere Prognose → weniger Überbestand → weniger Verderb
A72: MHD-Monitoring besonders für A-Artikel automatisieren | B72: Schnellere Reaktion bei ablaufenden Frischeprodukten
A73: Diebstahlprävention auf A-Artikel fokussieren | B73: Größter finanzieller Hebel

Sheet Schwundanalyse
A1: SCHWUNDANALYSE — INVENTUROPTIMIERUNG
A2: Analyse der Inventurdifferenzen nach Filiale, Monat, Kategorie und Ursache
A4: Filiale_Name | B4: Sum of Abweichung_Wert_EUR | C4: Average of Bestandsabweichung_%
A5: Filiale Nord | B5: 2232.14 | C5: -1.9633947
A6: Filiale Ost | B6: 2155.68 | C6: -2.0551909
A7: Filiale Süd | B7: 1814.61 | C7: -1.8499625
A8: Filiale Zentrum | B8: 3152.72 | C8: -2.3804558
A9: Filiale West | B9: 2196.55 | C9: -1.8729889
A10: Grand Total | B10: 11551.7 | C10: -2.0243986
A18: Monat_Name | B18: Sum of Abweichung_Wert_EUR
A19: Januar | B19: 670.98
A20: Februar | B20: 625.21
A21: März | B21: 842.81
A22: April | B22: 1266.47
A23: Mai | B23: 821.7
A24: Juni | B24: 959.61
A25: Juli | B25: 1226.18
A26: August | B26: 952.48
A27: September | B27: 819.77
A28: Oktober | B28: 876.7
A29: November | B29: 972.12
A30: Dezember | B30: 1517.67
A31: Grand Total | B31: 11551.7
A39: Kategorie | B39: Sum of Abweichung_Wert_EUR | C39: Average of Bestandsabweichung_%
A40: Butter | B40: 703.03 | C40: -0.90832327
A41: Joghurt | B41: 3147.89 | C41: -2.422095
A42: Käse | B42: 2634.48 | C42: -1.6958078
A43: Milch | B43: 3743.51 | C43: -2.5930118
A44: Quark | B44: 911.84 | C44: -2.1644225
A45: Sahne | B45: 410.95 | C45: -1.4358343
A46: Grand Total | B46: 11551.7 | C46: -2.0243986
A57: Abweichung_typ | B57: Count of Abweichung_Typ
A58: Perfekt | B58: 81
A59: Schwund | B59: 669
A60: Überbestand | B60: 150
A61: Grand Total | B61: 900
A75: Ereignis | B75: Sum of Abweichung_Wert_EUR
A76: Black Friday | B76: 972.12
A77: Karneval | B77: 625.21
A78: Normal | B78: 7170.23
...

Sheet Ursachenanalyse
A1: URSACHENANALYSE — INVENTURDIFFERENZEN
A2: Klassifikation der Bestandsabweichungen nach Ursache
A4: Ursachen | B4: Count of Ursachen | C4: Sum of Abweichung_Wert_EUR
A5: Buchungsfehler Wareneingang | B5: 131 | C5: 2270.41
A6: Diebstahlrisiko | B6: 63 | C6: 1805.41
A7: Kassenfehler (Überbestand) | B7: 136 | C7: 883.55
A8: MHD - Prozessfehler | B8: 30 | C8: 497.73
A9: Normal/Gering | B9: 231 | C9: 1236.95
A10: Prozessfehler | B10: 245 | C10: 4129.77
A11: Verderb - Abgelaufen | B11: 64 | C11: 727.88
A12: Grand Total | B12: 900 | C12: 11551.7

Sheet Prognose
A1: PROGNOSE — SCHWUND-VORHERSAGE
A2: Vorhersage des monatlichen Schwund-Wertes mittels Moving Average
A4: Monat_Nr | B4: Monat_Name | C4: Actual_Schwund_EUR | D4: 3-Monats-Durchschnitt | E4: Prognose | F4: Absoluter_Fehler | G4: Prozentualer_Fehler_%
A5: 1 | B5: Januar | C5: =SUMIFS(Rohdaten!N:N,Rohdaten!G:G,A5) -> 670.98
A6: 2 | B6: Februar | C6: =SUMIFS(Rohdaten!N:N,Rohdaten!G:G,A6) -> 625.21
A7: 3 | B7: März | C7: =SUMIFS(Rohdaten!N:N,Rohdaten!G:G,A7) -> 842.81
A8: 4 | B8: April | C8: =SUMIFS(Rohdaten!N:N,Rohdaten!G:G,A8) -> 1266.47 | D8: =AVERAGE(C5:C7) -> 713 | E8: =D8 -> 713 | F8: =ABS(C8-D8) -> 553.47 | G8: =IF(C8=0,0,F8/C8*100) -> 43.701785
A9: 5 | B9: Mai | C9: =SUMIFS(Rohdaten!N:N,Rohdaten!G:G,A9) -> 821.7 | D9: =AVERAGE(C6:C8) -> 911.49667 | E9: =D9 -> 911.49667 | F9: =ABS(C9-D9) -> 89.796667 | G9: =IF(C9=0,0,F9/C9*100) -> 10.928157
A10: 6 | B10: Juni | C10: =SUMIFS(Rohdaten!N:N,Rohdaten!G:G,A10) -> 959.61 | D10: =AVERAGE(C7:C9) -> 976.99333 | E10: =D10 -> 976.99333 | F10: =ABS(C10-D10) -> 17.383333 | G10: =IF(C10=0,0,F10/C10*100) -> 1.8114998
A11: 7 | B11: Juli | C11: =SUMIFS(Rohdaten!N:N,Rohdaten!G:G,A11) -> 1226.18 | D11: =AVERAGE(C8:C10) -> 1015.9267 | E11: =D11 -> 1015.9267 | F11: =ABS(C11-D11) -> 210.25333 | G11: =IF(C11=0,0,F11/C11*100) -> 17.14702
A12: 8 | B12: August | C12: =SUMIFS(Rohdaten!N:N,Rohdaten!G:G,A12) -> 952.48 | D12: =AVERAGE(C9:C11) -> 1002.4967 | E12: =D12 -> 1002.4967 | F12: =ABS(C12-D12) -> 50.016667 | G12: =IF(C12=0,0,F12/C12*100) -> 5.2512039
A13: 9 | B13: September | C13: =SUMIFS(Rohdaten!N:N,Rohdaten!G:G,A13) -> 819.77 | D13: =AVERAGE(C10:C12) -> 1046.09 | E13: =D13 -> 1046.09 | F13: =ABS(C13-D13) -> 226.32 | G13: =IF(C13=0,0,F13/C13*100) -> 27.607744
A14: 10 | B14: Oktober | C14: =SUMIFS(Rohdaten!N:N,Rohdaten!G:G,A14) -> 876.7 | D14: =AVERAGE(C11:C13) -> 999.47667 | E14: =D14 -> 999.47667 | F14: =ABS(C14-D14) -> 122.77667 | G14: =IF(C14=0,0,F14/C14*100) -> 14.00441
A15: 11 | B15: November | C15: =SUMIFS(Rohdaten!N:N,Rohdaten!G:G,A15) -> 972.12 | D15: =AVERAGE(C12:C14) -> 882.98333 | E15: =D15 -> 882.98333 | F15: =ABS(C15-D15) -> 89.136667 | G15: =IF(C15=0,0,F15/C15*100) -> 9.1693069
A16: 12 | B16: Dezember | C16: =SUMIFS(Rohdaten!N:N,Rohdaten!G:G,A16) -> 1517.67 | D16: =AVERAGE(C13:C15) -> 889.53 | E16: =D16 -> 889.53 | F16: =ABS(C16-D16) -> 628.14 | G16: =IF(C16=0,0,F16/C16*100) -> 41.388444
A18: MAPE (Forecast - Genauigkeit) | B18: =AVERAGE(G8:G16) -> 19.001064 | C18: %
A36: ERGEBNIS
A37: Der 3-Monats-Moving-Average erreicht einen MAPE von 19%
A38: Die Prognose zeigt die saisonalen Peaks korrekt, reagiert aber verzögert auf plötzliche Veränderungen.
A39: Empfehlung: Saisonale Anpassung (Saison-Index) würde die Prognosegenauigkeit verbessern.

Sheet Dashboard
A1: INVENTUROPTIMIERUNG — DASHBOARD
A2: Datenbasierte Analyse zur Verbesserung der Bestandsgenauigkeit
A4: GESAMTSCHWUND | D4: BESTANDSGENAUIGKEIT | G4: Ø SCHWUNDQUOTE | J4: ÜBERBESTAND (KASSENFEHLER)
A5: =SUMIFS(Rohdaten!N:N,Rohdaten!M:M,"Schwund") -> 10566.65 | D5: =ROUND((1-SUM(Rohdaten!N:N)/SUM(Rohdaten!I:I))*100,1) & "%" -> 96,3% | G5: =ROUND(ABS(AVERAGEIFS(Rohdaten!L:L,Rohdaten!M:M,"Schwund")),1) & "%" -> 3,1% | J5: =COUNTIF(Rohdaten!M:M,"Überbestand") -> 150
A7: ="Schwund Fälle: " & COUNTIF(Rohdaten!M:M,"Schwund") & " von 900" -> Schwund Fälle: 669 von 900 | D7: Ziel: > 97% | G7: Ziel: < 1.5% | J7: ="Anteil: " & ROUND(COUNTIF(Rohdaten!M:M,"Überbestand")/900*100,1) & "%" -> Anteil: 16,7%
A42: TOP 3 HANDLUNGSEMPFEHLUNGEN
A43: 1. | B43: A-Artikel wöchentlich zählen → 80% des Schwund-Werts kontrolliert
A44: 2. | B44: MHD-Prozess automatisieren → 15% Fehlerrate eliminieren
A45: 3. | B45: Filiale Zentrum: Diebstahlprävention → Höchster Schwund reduziert

Sheet Ergebnisse
A1: ERGEBNISSE & EMPFEHLUNGEN
A2: Zusammenfassung der Inventuroptimierung-Analyse
A4: PROJEKTZUSAMMENFASSUNG
A6: Zielsetzung | B6: Entwicklung eines datenbasierten Konzepts zur Verbesserung der Bestandsgenauigkeit im Einzelhandel
A7: Datengrundlage | B7: Simulierte Inventurdaten: 5 Filialen, 15 Artikel, 12 Monate (900 Datensätze)
A8: Methoden | B8: ABC-Analyse, Schwundanalyse (Pivot), Ursachenklassifikation, Prognose, KPI-Dashboard
A9: Tools | B9: Microsoft Excel (Pivot Tables, VLOOKUP, Formeln, Diagramme), Power BI
A10: Datenquelle | B10: Basierend auf Praxiserfahrung im filialbasierten Einzelhandel (Lidl, TEDi)
A13: KERNERGEBNISSE
A15: 1. Filiale Zentrum verursacht den höchsten Schwund-Wert (3.152,72€) — höchstes Diebstahlrisiko im Stadtgebiet
A16: 2. Dezember, April und Juli zeigen die höchsten saisonalen Schwund-Peaks (Weihnachten, Ostern, Sommerhitze)
A17: 3. Milch und Joghurt verursachen den größten Schwund durch kurze MHD (7-14 Tage)
A18: 4. 74% aller Datensätze zeigen Schwund, 17% Überbestand (Kassenfehler), 9% sind perfekt
A19: 5. 15% der MHD-Reduzierungsprozesse weisen Fehler auf (Zählfehler, FIFO-Fehler, Produkt übersehen)
A20: 6. ABC-Analyse: ~20% der Artikel verursachen ~80% des finanziellen Schwund-Verlustes
A21: 7. Freitag und Samstag verursachen zusammen ~55% des wöchentlichen Schwunds
A24: HANDLUNGSEMPFEHLUNGEN
A25: # | B25: Maßnahme | C25: Erwarteter Nutzen
A26: 1 | B26: A-Artikel wöchentlich per Cycle Count zählen | C26: Frühzeitige Schwund-Erkennung bei verlustreichsten Produkten
A27: 2 | B27: MHD-Monitoring automatisieren (Scanner statt manuell) | C27: Reduzierung der Verderb-Rate und MHD-Prozessfehler
A28: 3 | B28: Diebstahlprävention in Filiale Zentrum verstärken | C28: Reduzierung des höchsten Schwund-Standorts
A29: 4 | B29: Kassenschulungen für Mitarbeiter durchführen | C29: Reduzierung Kassenfehler-bedingter Überbestände
A30: 5 | B30: MHD-Checks morgens vor Kundenansturm durchführen | C30: Weniger Prozessfehler an Freitag/Samstag
A31: 6 | B31: FIFO-Prinzip konsequent umsetzen | C31: Weniger versteckte abgelaufene Ware
A32: 7 | B32: Bestellmengen bei hoher Reduzierungsquote anpassen | C32: Weniger Überbestand und Verderb
A33: 8 | B33: Forecast-Genauigkeit für A-Artikel priorisieren | C33: Bessere Prognose → optimierte Bestellmengen
A36: Erwarteter Nutzen
A38: Reduzierung der Schwundquote von ~2% auf <1.5%
A39: Geschätzte Einsparung: ca. €4.000–6.000 pro Filiale pro Jahr
A40: Verbesserung der Bestandsgenauigkeit auf >97%
A41: Reduzierung der MHD-Prozessfehler von 15% auf <5%
